File: development/xps-2.4.92/examples/3.vms
VAMAS Surface Chemical Analysis Standard Data Transfer Format 1988 May 4




1
Experiment Type: XPS
NORM
REGULAR
7
0
0
0
0
0
7


2008
10
9
15
9
42
0
0
XPS

1486.6
20.0
1E37
1E37
1E37
1E37
FAT
50.00
5.0
4.500
1E37
200
200
1E37
1E37


-1
binding energy
eV
92.0
-0.100
1
count rate
c/s
pulse counting
0.200
5
70E-9
1E37
1E37
1E37
0
121
7551
38977
12064
11493
11731
11607
11556
11601
11678
11941
11709
11705
11673
12093
11891
11950
11924
12219
12050
12402
12359
12443
12724
12881
13072
13499
13568
14110
14413
15040
15848
16809
17450
18379
19776
21146
22730
24230
25922
27853
29049
30993
32359
32587
33498
33710
33512
32813
32089
30520
29101
27365
25238
23547
21653
19958
18511
17476
16363
15604
15410
14747
14692
14898
15141
15413
16068
16869
17996
18719
20326
21842
23641
25428
27585
29982
31768
33887
35800
36831
38039
38895
38977
37998
37114
35249
33450
31533
28319
26006
23547
20751
19007
17132
15375
13788
12490
11779
11153
10317
10005
9647
9435
9089
8800
8754
8485
8268
8226
8085
8187
7920
7940
7886
7944
7765
7788
7561
7634
7806
7551
7613
7605


2008
10
9
15
9
42
0
0
XPS

1486.6
20.0
1E37
1E37
1E37
1E37
FAT
50.00
5.0
4.500
1E37
200
200
1E37
1E37


-1
binding energy
eV
405.0
-0.100
1
count rate
c/s
pulse counting
0.200
50
70E-9
1E37
1E37
1E37
0
101
268053
278732
270900
269539
270771
270082
269611
269825
270192
270219
270120
270156
271631
269955
270289
270332
270435
271014
271363
270507
271004
271101
271498
271906
270487
271889
271832
270492
270892
270839
272353
271080
272195
272310
272058
272167
272756
273315
272758
273588
273753
273336
274116
274415
274015
275676
274731
275478
276224
276796
276601
276452
278732
276958
277115
278220
277736
277917
277763
277499
277163
278350
277463
276771
275978
275931
275942
275263
275019
273738
273177
273251
272697
272735
272056
271145
271812
272124
270940
271239
270466
270399
270422
270280
271385
270859
270143
270101
269695
269801
270234
268910
269690
269988
269973
268691
269742
269935
268689
269389
268053
268926
270344


2008
10
9
15
9
42
0
0
XPS

1486.6
20.0
1E37
1E37
1E37
1E37
FAT
50.00
5.0
4.500
1E37
200
200
1E37
1E37


-1
binding energy
eV
295.0
-0.100
1
count rate
c/s
pulse counting
0.200
10
70E-9
1E37
1E37
1E37
0
151
33335
50384
34653
34699
34829
34625
35000
34303
34657
34711
34607
34660
34861
34726
34723
34825
34757
34828
34686
34885
34866
34265
34374
35122
34435
34446
34832
34591
34879
34708
34708
35254
34286
34767
34858
34507
34699
34775
34806
34970
34892
34557
35072
34944
34581
34679
34688
34429
34830
34783
34918
34950
34679
35044
34797
35050
35120
35171
35157
34811
34933
34984
35098
35449
35169
35185
35298
35073
35261
35339
35454
35939
35981
35977
35784
36049
36300
36600
36865
37315
37576
37867
38105
38738
39331
39718
40159
41265
42309
42968
43704
44653
45168
46381
47301
47636
48031
49094
49447
49876
50384
50195
49966
48470
48667
47751
47145
46594
45365
44031
43594
42479
41038
40781
39463
38837
37557
37304
36938
36092
36038
35465
35040
34998
34799
34596
34010
33996
34292
33957
33825
33637
34145
33709
34089
33975
33581
33520
33511
33853
33418
34160
33544
33439
33690
33594
33464
33576
33349
33335
33806
33665
33465


2008
10
9
15
9
42
0
0
XPS

1486.6
20.0
1E37
1E37
1E37
1E37
FAT
50.00
5.0
4.500
1E37
200
200
1E37
1E37


-1
binding energy
eV
175.0
-0.100
1
count rate
c/s
pulse counting
0.200
50
70E-9
1E37
1E37
1E37
0
201
167940
181557
169862
171156
170312
170475
170784
170206
171179
170608
170353
170587
170099
170641
170424
170985
171718
171344
170546
170957
171164
171863
170594
170516
170988
171713
170991
170962
171567
171103
171097
171296
171058
171385
171923
171324
170876
170843
171623
170702
171446
172419
172238
171922
172184
171421
172566
171815
172189
172149
173366
172764
172817
172766
173226
173343
172812
172957
172576
172698
172541
172772
172991
172273
171771
172120
171714
171885
171905
172109
171898
171755
171084
171320
171711
171064
170756
172025
170995
171501
170955
171300
171102
171407
171368
171244
171381
170942
171319
170607
171250
171803
171619
172648
172024
172816
172207
172341
172930
172810
172635
172757
172523
172953
174219
173333
174035
173376
173497
173815
174856
174738
173749
174718
175054
175333
176340
175987
177369
177070
177247
178718
179315
179256
179394
180118
179929
180688
181224
181318
181208
181557
181430
181053
180892
180309
179392
179489
178845
178519
178078
176780
176341
174945
175072
174264
172637
172681
171000
172009
171206
171096
170354
169928
170059
169788
169218
169268
168834
169572
169865
169416
168529
169015
169631
169155
169009
169542
168559
169184
168236
167940
168933
168509
170174
169224
169168
168954
168495
168840
169314
168851
169930
168891
168960
169504
169357
169712
170030
169950
170282
170336
170204
171027
169970
171301
170677
171085
171095
171005
171575
171657
171837


2008
10
9
15
9
42
0
0
XPS

1486.6
20.0
1E37
1E37
1E37
1E37
FAT
50.00
5.0
4.500
1E37
200
200
1E37
1E37


-1
binding energy
eV
410.0
-0.100
1
count rate
c/s
pulse counting
0.200
5
70E-9
1E37
1E37
1E37
0
201
27864
29423
28120
28520
28584
28401
28870
28331
28396
28510
28322
28414
28272
28298
28490
28710
28354
28320
28520
28361
28494
28280
28586
28301
28136
28276
28163
28361
28302
28586
28398
28607
28703
28264
28401
28560
28213
28453
28511
28765
28370
28191
28200
28304
28222
28149
28337
28006
28560
28569
28341
28457
28537
28449
28033
28253
28288
28387
28403
28649
28566
28451
28424
28878
28303
28251
28471
28494
28007
28463
28546
28479
28473
28490
28288
28355
28582
28586
28285
28135
28580
28748
28639
28298
28528
28803
28805
28827
28819
28603
28760
28785
28854
28802
28886
29173
28909
28889
28965
29140
29278
28770
29061
28934
28901
29394
28847
29137
29423
29199
28989
29074
29117
28949
29189
28915
28795
29130
28963
28870
28824
29088
28780
28880
28651
28431
28530
28573
28451
28604
28711
28483
28614
28442
28350
28316
28112
28287
28644
28346
28006
28389
28456
28342
28215
28266
28210
28214
28552
28287
28179
28175
28182
28392
28243
28392
28135
28295
27892
28067
28028
28070
28000
27952
28065
28006
28582
28206
28241
28184
28095
28095
28064
28095
28007
27987
28248
28422
28357
27988
28166
27915
27864
28257
27944
28224
28109
28136
28030
28080
27992
28114
28319
28036
28482
28003
28126
28075
28246
27910
28141
28345
28362


2008
10
9
15
9
42
0
0
XPS

1486.6
20.0
1E37
1E37
1E37
1E37
FAT
50.00
5.0
4.500
1E37
200
200
1E37
1E37


-1
binding energy
eV
10.0
-0.100
1
count rate
c/s
pulse counting
0.200
25
70E-9
1E37
1E37
1E37
0
121
13944
31747
18894
18997
18734
18787
18934
18959
19053
19077
19360
19258
19432
19501
19954
20118
20318
20467
20624
21277
21474
22032
22315
23067
23509
23911
24317
25181
25703
26613
27326
27934
28456
28834
29193
29662
30487
30367
30279
30388
30630
30507
30450
29990
30271
29934
29906
29613
29640
29178
29469
29101
29388
29485
29776
30159
29833
30178
30669
30565
30754
31248
31026
31312
31374
31747
31310
31078
30763
30788
30350
30275
29790
29313
28613
28353
27453
26596
26053
25534
24198
23894
23061
22676
21551
21188
20152
19908
19525
18845
18409
18169
17962
17753
17251
17191
17007
16865
16356
16421
16044
15754
15363
15418
15225
15105
14920
14752
14462
14315
14393
14362
14291
14267
14348
13944
14085
14172
14250
14147
13992
14120
14170


2008
10
9
15
9
42
0
0
XPS

1486.6
20.0
1E37
1E37
1E37
1E37
FAT
50.00
5.0
4.500
1E37
200
200
1E37
1E37


-1
binding energy
eV
1000.0
-0.5
1
count rate
c/s
pulse counting
0.200
70E-9
1E37
0
627
12797
12925
12905
12683
12436
12561
12334
12273
12153
11999
12158
11846
12056
11857
11776
11818
11856
12045
11933
12270
12209
12286
12605
12791
12327
12277
12334
12066
11784
11509
11363
11359
11349
11334
11464
11327
11418
11393
11579
11265
11417
11466
11296
11031
11147
11016
10757
10438
10642
10626
10698
10594
10661
10838
10606
10667
10579
10537
10639
10630
10504
10537
10585
10146
10355
10305
10508
10559
10323
10506
10565
10358
10409
10528
10444
10441
10304
10368
10463
10356
10320
10560
10314
10142
10364
10439
10293
10345
10252
10190
10225
10256
10248
10207
10221
10167
10176
10211
9951
10143
10151
10154
10094
10121
10115
10231
10033
10190
10069
10087
9998
9795
9926
9922
9846
9762
9752
9784
9852
9761
9604
9546
9716
9780
9824
9706
9820
9477
9760
9682
9786
9801
9602
9711
9735
9671
9675
9728
9413
9819
9625
9770
9661
9755
9546
9699
9666
9637
9687
9672
9444
9558
9506
9710
9631
9469
9549
9528
9580
9608
9435
9376
9560
9315
9403
9353
9621
9536
9660
9563
9373
9076
9174
8992
9162
9019
9017
9051
9028
9098
9064
8872
8971
9020
8860
8942
9043
8862
8755
8969
9076
8949
9178
8856
9065
8864
9053
8853
9019
9037
9058
8715
9028
8913
8964
8828
8793
9013
9015
8889
8921
8906
8834
9173
8945
8966
8964
9107
9069
9016
8851
8911
8819
8713
8779
8637
8829
8588
8747
8811
8820
8660
8648
8708
8749
8590
8630
8755
8556
8732
8703
8683
8666
8470
8641
8576
8645
8347
8649
8667
8647
8627
8431
8683
8752
8585
8494
8581
8540
8456
8512
8523
8476
8602
8283
8458
8633
8496
8637
8464
8564
8618
8474
8620
8849
8861
8589
8705
8747
8590
8383
8692
8598
8572
8586
8497
8734
8689
8675
8686
8817
8466
8502
8269
8271
8481
8266
8150
8175
8201
8302
8301
8170
8155
8204
8175
8005
7929
7912
8033
7875
7914
7988
8201
8368
8219
7848
7818
7789
7628
7822
7747
7735
7814
7708
7619
7922
7723
7741
7773
7824
7790
7775
7695
7978
7774
7580
7744
7733
7717
7660
7679
7793
7755
7555
7787
7620
7771
7685
7683
7689
7672
7758
7773
7655
7765
7794
7986
7864
7859
7686
7591
7785
7496
7769
7681
7646
7627
7557
7763
7419
7532
7402
7700
7598
7634
7715
7694
7566
7651
7812
7796
7521
7759
7689
7787
7542
7703
7636
7721
7682
7570
7668
7760
7747
7582
7741
7774
7549
7667
7643
7798
7645
7678
7760
7723
7531
7664
7636
7729
7659
7853
8075
8020
8123
8170
8037
7867
7750
7534
7573
8034
8206
8650
8592
8155
7819
7385
6927
6896
6918
6802
6749
6825
6871
6613
6641
6653
6634
6550
6683
6460
6682
6482
6573
6638
6729
6578
6542
6646
6566
6623
6791
6858
6901
6581
6497
6312
6209
6035
6067
6200
6119
6045
6057
6368
6660
7361
8076
8191
7164
6219
5745
5810
5732
5939
5734
6079
6016
6033
6001
5940
5785
5787
5741
5824
5847
5811
5743
5712
5739
5730
5867
5701
5950
5708
5723
5772
5687
5736
5735
5816
5696
5731
5884
5751
5800
5768
5826
5693
5547
5800
5820
5686
5752
5679
5655
5660
5752
5693
5821
5803
5613
5753
5747
5764
5867
5771
5817
5854
5742
5751
5801
5714
5739
5838
5712
5689
5812
5813
5828
5666
5765
5873
5756
5638
5818
5835
6031
5711
5745
5817
5711
5781
5996
6088
5898
5796
5734
5719
5677
5780
5726
5613
5930
5650
5801
5700
5710
5679
5717
5838
5745
5742
5769
5708
5790
5824
5682
5786
5661
5556
5651
5832
5619
5573
5719
5770
5698
5696
5799
5559
5721
5809
5660
5707
5725
5613
5770
5921
5816
5682
5783
5668
5706
5670
5804
5660
5700
5652
5671
5621
5598
5637
5747
5669
5635
5648
5685
5620
5599
5610
5517
5566
5620
5580
5618
5526
5554
5438
5559
5471
5494
5534
5575
5392
5355
5465
5414
5416
5279
5378
5431
5541
5649
5896
6177
6329
6070
5482
5097
5266
4993
4970
4807
4734
4714
4824
4659
4692
4727
4834
5175
5477
5954
6096
5580
5069
4665
4366
4163
4057
4044
4003
3980
3946
3877
3893
3811
3852
3781
3828
3749
3916
3654
3718
3727
3793
3727
3624
3709
3632
3811
3699
3586
3675
3495
3547
3627
3627
3546
3522
3599
3640
3574
3618
3578
3659
3529
3555
3514
3528
3639
4033
4748
5071
4327
3641
3441
3453
3527
3453
3450
3435
3635
3554
3544
3568
3452
3511
3449
3337
3480
3506
3463
3482
3438
3527
3494
3445
3453
3384
3410
3467
3323
3443
3465
3528
3460
3456
3485
3378
3389
3450
3360
3429
3557
3443
3455
3505
3503
3402
3371
3538
3453
3405
3496
3404
3431
3498
3488
3502
3607
3577
3521
3426
3537
3465
3437
3429
3500
3435
3406
3513
3374
3469
3397
3487
3453
3495
3390
3387
3464
3429
3449
3516
3432
3373
3457
3473
3455
3499
3456
3533
3424
3359
3501
3386
3567
3502
3543
3379
3471
3450
3359
3436
3496
3418
3505
3505
3600
3411
3515
3584
3529
3431
3469
3517
3519
3478
3571
3528
3463
3536
3526
3533
3547
3680
3637
3592
3416
3435
3521
3513
3410
3415
3507
3420
3518
3428
3423
3323
3455
3514
3395
3409
3382
3425
3501
3479
3439
3310
3401
3361
3370
3431
3425
3426
3340
3352
3288
3337
3261
3289
3314
3295
3272
3312
3416
3243
3419
3389
3326
3279
3381
3413
3308
3445
3444
3280
3351
3394
3294
3351
3304
3231
3073
3067
3056
3101
2980
2904
2811
2727
2584
2575
2626
2495
2535
2466
2651
3721
6829
5337
3164
5021
8236
3950
2006
1634
1649
1697
1858
1829
1798
1888
1855
1708
1645
1388
1289
1241
1222
1259
1302
1283
1260
1230
1202
1274
1289
1323
1356
1337
1402
1365
1267
1183
1235
1063
1135
1134
1150
1095
1092
1167
1210
1136
1146
1090
941
996
933
932
953
957
946
932
914
943
934
915
874
935
917
895
898
944
911
854
823
904
904
859
862
849
777
797
723
786
767
772
904
1182
1238
1143
1190
1227
890
734
627
end of experiment