File: development/xps-2.1/examples/cs.vms
VAMAS Surface Chemical Analysis Standard Data Transfer Format 1988 May 4




1
Experiment Type: XPS
NORM
REGULAR
5
0
0
0
0
0
5


2007
8
15
13
48
25
0
0
XPS

1486.6
20.0
1E37
1E37
1E37
1E37
FAT
50.00
5.0
4.500
1E37
1200
1200
1E37
1E37


-1
binding energy
eV
1000.0
-0.5
1
count rate
c/s
pulse counting
0.200
70E-9
1E37
0
69
1965
2003
1916
1909
1926
1819
1801
1818
1789
1750
1813
1758
1825
1829
1763
1853
1856
1837
1886
1987
1933
2071
2099
2015
2109
1924
1945
1862
1837
1769
1735
1751
1693
1631
1606
1553
1482
1554
1592
1487
1506
1525
1514
1494
1501
1497
1465
1506
1443
1472
1483
1496
1482
1461
1452
1424
1445
1432
1452
1502
1505
1407
1365
1422
1466
1422
1433
1459
1421
1387
1473
1422
1462
1350
1451
1416
1460
1314
1426
1382
1363
1296
1346
1360
1405
1391
1358
1361
1466
1371
1370
1438
1397
1375
1328
1331
1332
1386
1362
1317
1343
1370
1314
1355
1328
1352
1385
1365
1261
1302
1347
1328
1333
1333
1375
1370
1284
1317
1303
1344
1318
1315
1286
1339
1296
1360
1338
1367
1333
1255
1249
1195
1306
1256
1289
1289
1255
1271
1316
1346
1265
1350
1329
1337
1258
1260
1258
1273
1263
1237
1265
1229
1279
1240
1217
1208
1236
1254
1247
1246
1209
1266
1254
1241
1223
1255
1429
1267
1256
1412
1275
1292
1197
1219
1227
1196
1214
1196
1196
1162
1236
1207
1181
1177
1172
1240
1139
1132
1232
1115
1192
1154
1232
1156
1142
1140
1093
1183
1098
1152
1166
1191
1200
1156
1130
1160
1137
1134
1142
1124
1091
1077
1151
1130
1135
1165
1126
1097
1120
1149
1165
1102
1079
1147
1108
1091
1084
1110
1113
1092
1122
1058
1096
1085
1149
1136
1108
1033
1102
1097
1064
1055
1121
1105
1063
1096
1137
1020
1079
1096
1062
1088
1035
1107
1081
1054
1094
1108
1089
1102
1084
988
1056
1047
1055
1069
1105
1013
1065
1073
1040
1049
1059
1048
1098
1068
1050
1054
1042
1093
1052
1091
1051
1043
1020
1032
982
1021
1017
1096
1039
1011
997
1002
999
1039
1080
1039
1040
1030
1013
997
1038
976
983
997
1013
1004
989
1016
994
1044
1050
1126
1183
1135
1025
992
944
969
1025
933
1004
1014
985
988
944
921
947
978
976
1026
940
948
1000
980
957
962
994
949
997
920
1013
964
951
1019
956
944
906
934
893
943
932
937
976
960
997
929
975
943
1006
952
917
913
945
909
897
950
921
931
910
966
905
941
887
904
894
905
901
914
885
964
918
952
907
890
954
959
971
920
922
909
937
900
903
879
852
953
896
925
930
896
853
957
883
939
919
916
904
936
976
930
910
881
940
985
933
883
971
910
876
968
940
928
916
921
957
940
887
897
923
934
914
876
909
941
935
937
930
884
938
906
916
934
883
942
924
897
955
935
932
904
899
886
892
852
842
891
845
801
949
845
858
877
934
919
1094
1528
1824
1326
966
901
864
853
816
867
863
895
838
878
850
816
817
858
842
814
800
762
811
826
824
801
809
819
786
839
796
745
774
849
814
831
815
854
813
800
825
763
851
798
789
818
761
823
812
837
737
768
799
809
805
769
797
800
801
799
825
834
796
799
808
805
792
753
777
727
780
783
768
814
789
795
768
780
795
779
816
799
857
771
731
736
780
748
789
856
809
796
791
798
728
770
782
742
749
785
766
763
715
723
767
739
722
721
801
758
773
793
735
781
762
715
788
799
748
781
732
758
798
765
790
741
757
785
811
750
776
767
785
759
813
773
793
857
728
723
781
694
785
788
752
720
761
768
808
742
740
797
786
806
803
782
793
756
768
781
768
774
742
773
789
774
823
771
763
767
767
801
779
820
759
828
789
758
826
793
724
786
794
832
790
806
785
783
771
757
848
791
785
826
743
825
746
829
776
797
902
780
857
791
802
851
828
815
782
776
811
823
794
807
750
756
849
792
727
757
759
793
831
794
863
887
943
971
956
917
904
814
775
761
717
714
742
707
735
714
653
649
643
643
633
716
663
647
758
1042
1871
2532
1153
648
571
575
551
579
567
568
619
666
582
625
544
549
579
549
539
547
533
559
554
542
533
556
567
561
520
525
554
534
506
524
528
573
568
573
563
534
560
501
507
518
546
520
520
545
594
554
517
568
571
587
560
522
557
519
561
547
560
557
557
588
558
573
574
591
588
579
540
541
575
580
577
558
597
541
557
620
576
570
571
631
602
604
625
645
610
620
561
622
565
550
609
586
581
553
557
599
600
621
600
594
667
639
732
738
771
797
760
776
706
611
622
609
581
550
526
542
551
498
521
496
464
429
440
463
510
637
912
1861
2263
1229
671
554
524
453
456
422
487
534
554
501
461
364
352
362
382
367
368
382
398
410
392
387
401
455
482
516
551
545
434
418
393
343
340
299
324
286
306
256
252
256
277
226
227
206
192
211
236
360
1329
2380
960
278
197
175
188
142
169
192
254
278
245
203
165
159
144
128
136
161
153
138
190
162
161
135
146
138
129
131
133
111
145
135
133
140
116
147
127
140
122
133
130
126
139
141
121
141
147
137
133
132
157
130
113
121
121
145
105
137
146
144
134
138
158
148
143
148
131
134
158
159
150
147
147
136
116
146
118
119
127
102
106
142
143
166
127
137
137
132
129
175
144
147
146
144
147
125
131
122
102
109
112
78
129
108
100
92
84
104
90
106
100
108
95
106
81
95
92
99
113
114
100
96
97
114
110
102
101
91
123
97
88
116
83
94
89
85
103
79
89
96
100
107
98
101
106
101
100
69
93
104
98


2007
8
15
13
48
25
0
0
XPS

1486.6
20.0
1E37
1E37
1E37
1E37
FAT
50.00
5.0
4.500
1E37
1200
1200
1E37
1E37


-1
binding energy
eV
110.0
-0.100
1
count rate
c/s
pulse counting
0.200
10
70E-9
1E37
1E37
1E37
0
151
1579
23725
2497
2514
2407
2490
2484
2375
2464
2325
2366
2299
2349
2370
2209
2190
2281
2241
2271
2225
2274
2156
2153
2264
2158
2166
2184
2092
2146
2155
2138
2103
2073
1989
1999
2022
2053
2021
2048
2107
2008
2038
2012
2033
1947
2033
1949
1972
1935
2009
1977
1940
2020
2024
1958
2038
2087
2136
2071
2128
2176
2114
2366
2256
2421
2384
2537
2648
2760
2957
3094
3376
3739
3988
4436
5060
5511
6300
7057
8379
9316
10610
12058
13473
14877
16557
17930
19446
20861
22052
22885
23616
23725
23240
23023
22222
21029
19349
18121
16524
14832
13015
11306
9708
8660
7045
6089
5395
4504
4018
3478
3121
2783
2617
2506
2361
2219
2131
2161
2035
2011
2015
1915
1843
1811
1871
1831
1758
1799
1690
1730
1719
1755
1757
1728
1702
1630
1720
1667
1654
1680
1627
1647
1620
1716
1700
1662
1629
1579
1662
1656
1712
1618


2007
8
15
13
48
25
0
0
XPS

1486.6
20.0
1E37
1E37
1E37
1E37
FAT
50.00
5.0
4.500
1E37
1200
1200
1E37
1E37


-1
binding energy
eV
24.0
-0.100
1
count rate
c/s
pulse counting
0.200
50
70E-9
1E37
1E37
1E37
0
261
5179
8807
6855
6641
6608
6668
6538
6637
6687
6510
6627
6509
6417
6491
6384
6414
6411
6174
6555
6274
6207
6305
6203
6245
6173
6154
6333
6341
6143
6365
6320
6130
6305
6168
6317
6282
6157
6342
6182
6381
6407
6293
6425
6461
6360
6456
6616
6637
6629
6610
6681
6905
6814
6874
6965
6918
7114
7104
7024
7117
7093
7224
7331
7195
7262
7272
7416
7332
7321
7246
7119
7206
7129
7190
7228
7285
7225
7210
7350
7201
7379
7369
7463
7322
7459
7559
7399
7494
7533
7594
7618
7694
7640
7703
7556
7697
7686
7620
7665
7649
7813
7688
7716
7518
7698
7502
7348
7256
7201
7089
7097
7009
7083
6740
6844
6613
6831
6633
6616
6657
6637
6621
6541
6584
6502
6686
6687
6876
7068
6967
7085
7351
7477
7630
7543
7960
7906
8117
8288
8461
8644
8596
8807
8800
8754
8721
8663
8477
8571
8299
8334
8206
8009
8031
7870
7664
7709
7650
7550
7446
7468
7536
7440
7630
7491
7475
7619
7494
7580
7633
7719
7439
7538
7539
7509
7392
7524
7565
7682
7368
7620
7576
7455
7657
7409
7636
7389
7597
7464
7515
7636
7297
7413
7443
7213
7524
7092
7179
7355
7177
7080
7021
6805
6849
6795
6722
6602
6559
6455
6358
6315
6164
5943
6040
5894
5849
5752
5700
5696
5569
5604
5480
5573
5379
5403
5376
5354
5293
5327
5203
5193
5418
5319
5257
5309
5228
5278
5469
5328
5356
5358
5341
5354
5197
5329
5386
5392
5442
5289
5284
5179
5332
5223
5253
5274
5353
5425
5295
5257
5204
5367
5352
5444


2007
8
15
13
48
25
0
0
XPS

1486.6
20.0
1E37
1E37
1E37
1E37
FAT
50.00
5.0
4.500
1E37
1200
1200
1E37
1E37


-1
binding energy
eV
292.0
-0.100
1
count rate
c/s
pulse counting
0.200
40
70E-9
1E37
1E37
1E37
0
171
24562
114554
28786
27963
28163
27859
28163
28196
28339
27993
27615
28122
28091
27689
27765
27914
28106
28057
28258
28228
28132
28009
28251
28645
28418
28493
28472
28698
28929
29261
29035
28642
28833
29263
29075
29071
28985
29138
28948
28835
28487
28830
28995
28539
28767
28628
28744
28983
29119
29349
29564
29628
29985
30204
30401
30492
30942
31216
31988
32450
32965
33698
34205
34888
35886
36835
37896
38659
39527
41236
42453
44210
45894
47252
49281
51820
54130
56779
60755
65541
69808
74461
80650
86541
92735
98467
103944
107996
111816
114197
114543
114554
112011
107400
102601
95902
89647
81895
74124
67110
60221
53916
48462
43965
39986
36848
34365
32932
31257
30179
29435
28489
28110
27350
26966
26768
26803
26458
26190
25942
25824
25764
25460
25485
25320
25596
25588
25453
25257
25041
25031
25111
25153
25173
24912
24980
25006
24945
25062
25058
25198
24924
24984
24974
24767
24990
24892
25160
24616
24954
24943
24831
24995
24910
24932
24706
24778
24699
24562
24848
24914
24966
24980
24937
25135
25025
25131
24978
24831
25530
25476
25465
25611


2007
8
15
13
48
25
0
0
XPS

1486.6
20.0
1E37
1E37
1E37
1E37
FAT
50.00
5.0
4.500
1E37
1200
1200
1E37
1E37


-1
binding energy
eV
528.0
-0.100
1
count rate
c/s
pulse counting
0.200
3
70E-9
1E37
1E37
1E37
0
151
1543
2551
2469
2408
2493
2465
2419
2452
2429
2458
2344
2387
2426
2434
2498
2392
2462
2383
2431
2453
2364
2437
2467
2388
2453
2447
2400
2359
2415
2385
2356
2524
2365
2301
2323
2366
2452
2481
2410
2359
2342
2298
2496
2447
2426
2436
2492
2450
2466
2405
2443
2433
2499
2441
2367
2536
2422
2411
2386
2464
2457
2522
2471
2496
2494
2490
2385
2423
2528
2472
2489
2486
2427
2409
2401
2474
2474
2380
2423
2408
2503
2437
2359
2458
2476
2418
2465
2466
2535
2464
2422
2485
2458
2462
2430
2405
2521
2460
2390
2493
2401
2527
2551
2489
2428
1638
1718
1644
1710
1612
1701
1635
1651
1612
1678
1590
1733
1618
1649
1646
1592
1645
1655
1684
1612
1564
1561
1597
1583
1619
1575
1644
1580
1656
1563
1620
1584
1671
1555
1620
1627
1642
1554
1680
1567
1546
1585
1587
1576
1649
1611
1661
1543
end of experiment