File: gxps/gxps-2.1/examples/2.vms
VAMAS Surface Chemical Analysis Standard Data Transfer Format 1988 May 4




0
NORM
REGULAR
6
0
0
0
0
0
6


2001
5
11
11
44
35
0
0
XPS

1486.6
20.0
1E37
1E37
1E37
1E37
FAT
50.00
5.0
4.500
1E37
1200
1200
1E37
1E37


-1
binding energy
eV
1386.6
-0.5
1
counts
d
pulse counting
0.200
70E-9
1E37
0
189
19188
22685
22241
22351
21606
21267
21338
21030
20768
20402
20433
20363
19620
19648
19187
19062
18995
18639
18558
18363
18227
18053
17771
17562
17631
17515
17501
17013
17072
16938
16629
16633
16320
16287
16067
15881
15782
15800
15486
15680
15713
15351
15151
15096
14959
14865
14560
14577
14427
14342
14369
14181
14246
14145
14072
14005
14086
13622
13711
13663
13629
13499
13387
13192
13261
13256
13144
13068
12805
12750
12716
12749
12526
12692
12719
12515
12578
12326
12295
12319
12453
12190
12314
12095
11832
11816
11890
11897
11629
11605
11773
11467
11512
11465
11426
11481
11402
11296
11042
11288
11185
11028
10960
11081
10851
11127
10942
10816
10729
10710
10808
10691
10619
10614
10583
10591
10425
10376
10474
10282
10350
10326
10410
10211
10208
10166
10062
10062
10143
9939
9984
10043
10013
9898
10010
9854
9783
10052
10198
10048
9920
9944
9899
9826
9690
9758
9634
9887
9785
9620
9912
9683
9670
9746
9534
9726
9816
9891
9870
9732
9922
9846
9671
9697
9517
9509
9386
9078
8881
8820
8643
8453
8271
8162
7995
7957
7980
7934
7715
7789
7685
7716
7627
7634
7620
7453
7579
7614
7545
7716
7326
7455
7513
7470
7259
7362
7399
7368
7423
7333
7261
7317
7380
7041
7166
7199
7143
7084
7092
6922
6951
7026
6971
7029
6986
7090
6958
6733
6912
6974
6981
6944
6940
6878
6768
6893
6935
6800
6672
6833
6680
6723
6760
6632
6742
6741
6838
6669
6733
6618
6393
6639
6581
6458
6544
6535
6479
6494
6461
6555
6481
6509
6406
6453
6555
6447
6399
6244
6393
6360
6393
6284
6320
6306
6238
6097
6354
6340
6297
6164
6230
6110
6103
6076
6353
6066
6212
6129
6061
6129
6184
6158
6158
5996
6025
5941
5970
5889
6012
5798
5970
5946
5884
6064
5931
6002
5910
5867
5932
5779
5922
5742
5826
5857
5719
5808
5805
5902
5702
5849
5804
5889
5729
5788
5905
5802
5711
5731
5805
5673
5777
5682
5667
5727
5812
5623
5613
5675
5380
5614
5673
5618
5541
5514
5547
5638
5586
5682
5488
5483
5464
5502
5484
5514
5582
5479
5348
5478
5392
5582
5503
5484
5450
5477
5547
5412
5368
5309
5507
5342
5266
5305
5448
5535
5356
5294
5301
5369
5355
5426
5355
5324
5279
5366
5227
5303
5289
5128
5294
5104
5147
5331
5134
5276
5054
5360
5218
5315
5193
5216
5185
5141
5159
5115
5009
4858
5028
5034
4938
4992
4929
4919
4900
4937
4740
4937
5083
5186
5165
5232
5332
5071
4890
4966
4934
4758
4674
4631
4616
4456
4467
4442
4230
4357
4306
4294
4290
4228
4131
4108
4318
4143
4235
4285
4138
4324
4106
4202
4172
4105
4104
4165
4031
4056
4007
4055
4076
4082
3997
4034
3934
4000
3986
4036
3963
4109
3951
3879
4060
4024
3842
3836
3872
3950
3907
3855
3887
3764
3856
3889
3883
3692
3762
3731
3793
3756
3676
3819
3790
3800
3677
3713
3788
3663
3701
3682
3723
3731
3658
3635
3628
3606
3655
3702
3703
3624
3658
3628
3578
3582
3513
3556
3465
3584
3348
3494
3526
3619
3467
3429
3436
3432
3395
3329
3494
3410
3228
3386
3403
3370
3354
3439
3319
3388
3328
3336
3364
3284
3331
3341
3210
3244
3278
3344
3343
3244
3135
3171
3258
3243
3249
3169
3264
3181
3180
3147
3048
3173
3070
3067
3097
3106
3086
3075
3142
3043
3168
3054
3020
3017
3013
2905
2966
2929
2980
2927
2952
2959
2937
2955
2854
2928
2939
2963
2855
2946
2874
2843
2763
2902
2819
2887
2928
2752
2882
2915
2853
2806
2739
2807
2790
2745
2787
2761
2828
2767
2664
2862
2818
2751
2781
2753
2785
2782
2777
2744
2785
2647
2667
2736
2689
2601
2656
2699
2569
2579
2571
2586
2666
2671
2665
2597
2550
2573
2533
2568
2555
2522
2597
2528
2579
2514
2536
2470
2551
2531
2543
2426
2461
2540
2520
2564
2564
2474
2452
2496
2448
2477
2607
2547
2519
2413
2477
2352
2363
2417
2369
2413
2481
2433
2481
2449
2401
2479
2359
2367
2374
2321
2310
2436
2363
2348
2423
2384
2303
2366
2359
2337
2225
2204
2251
2173
2263
2211
2245
2179
2161
2246
2193
2246
2084
2217
2151
2173
2196
2243
2146
2132
2163
2210
2173
2134
2140
2158
2091
2070
2123
2244
2073
2187
2053
2087
2064
2064
2084
2111
2055
2080
2037
2067
2122
1981
2094
2116
2055
2034
2038
2020
2056
2091
1970
2039
1966
2027
1981
2025
2006
2062
2032
2006
1983
2023
2042
1947
2025
2111
1984
2031
1980
2014
1959
2003
1970
1947
1983
2060
1895
1981
1929
1904
1997
2023
1927
1935
1931
1952
1892
1919
1929
1871
1933
1936
2038
1968
1922
1874
1876
1999
1997
1982
1926
1953
1961
1919
1850
1881
1849
1795
1911
1889
1939
1918
1895
1851
1915
1906
1854
1846
1883
1890
1882
1846
1904
1883
1886
1916
1800
1878
1866
1850
1870
1823
1896
1885
1827
1839
1773
1800
1847
1831
1720
1849
1919
1753
1857
1772
1741
1848
1797
1846
1872
1894
1848
1871
1790
1775
1810
1748
1796
1687
1671
1761
1798
1690
1808
1689
1733
1721
1733
1731
1698
1702
1882
2181
2604
2546
2004
1791
1644
1716
1669
1708
1621
1672
1628
1709
1730
1580
1708
1572
1688
1603
1640
1668
1636
1573
1641
1674
1583
1652
1622
1526
1664
1661
1597
1606
1620
1627
1617
1634
1600
1596
1587
1639
1570
1585
1577
1667
1531
1656
1619
1522
1539
1568
1505
1515
1580
1535
1549
1649
1566
1575
1597
1522
1614
1635
1551
1643
1645
1549
1516
1641
1547
1494
1577
1519
1598
1557
1557
1559
1533
1586
1556
1526
1559
1496
1566
1603
1532
1526
1639
1579
1500
1553
1520
1555
1541
1582
1510
1517
1495
1550
1568
1555
1476
1518
1454
1524
1532
1473
1546
1534
1554
1612
1645
1472
1569
1463
1567
1547
1524
1528
1523
1502
1531
1516
1478
1481
1541
1443
1570
1538
1513
1461
1441
1555
1481
1549
1507
1507
1459
1495
1504
1578
1463
1513
1557
1478
1512
1538
1488
1434
1453
1480
1525
1429
1428
1480
1460
1493
1513
1460
1551
1393
1451
1430
1401
1418
1491
1516
1426
1417
1416
1458
1478
1492
1447
1390
1479
1442
1479
1461
1479
1472
1432
1430
1470
1516
1497
1454
1390
1423
1426
1396
1425
1385
1511
1520
1385
1436
1417
1482
1423
1416
1448
1538
1507
1444
1511
1480
1424
1409
1509
1445
1400
1452
1427
1445
1474
1491
1427
1486
1491
1499
1451
1491
1486
1510
1507
1467
1463
1449
1445
1448
1487
1473
1427
1433
1451
1462
1453
1359
1476
1468
1416
1453
1425
1507
1499
1545
1864
2355
2519
1747
1439
1446
1406
1388
1399
1389
1420
1515
1514
1446
1369
1448
1396
1416
1371
1437
1428
1441
1339
1400
1369
1397
1447
1394
1402
1441
1410
1470
1440
1410
1441
1388
1405
1448
1367
1425
1461
1442
1467
1426
1460
1420
1541
1473
1521
1450
1509
1495
1479
1478
1467
1438
1490
1457
1510
1543
1560
1537
1463
1490
1489
1553
1615
1569
1531
1612
1565
1559
1525
1523
1522
1561
1538
1627
1587
1580
1581
1662
1624
1614
1761
1719
1664
1701
1597
1617
1523
1654
1586
1708
1671
1668
1610
1771
1827
1807
1858
1826
1896
1830
1715
1706
1670
1695
1604
1591
1618
1645
1717
1633
1723
1866
1908
2105
2326
2292
2140
1911
1766
1603
1509
1436
1364
1491
1474
1448
1328
1541
1482
1560
1984
3527
4650
2745
1561
1321
1150
1076
1143
1103
1157
1239
1328
1189
1145
1184
1209
1243
1169
1223
1145
1116
1076
1018
1001
962
905
934
984
930
1020
1054
1125
1140
1385
1552
1605
1446
1155
1014
849
816
792
752
757
710
687
575
602
584
592
720
2195
4591
2313
585
427
371
420
391
366
329
468
609
457
451
363
312
300
284
321
318
317
328
303
290
287
305
319
265
277
289
303
252
295
289
295
275
307
302
298
271
276
282
281
287
282
264
305
282
271
263
304
294
285
289
303
267
283
287
297
271
290
296
262
282
270
235
300
262
277
305
280
298
309
286
312
295
303
302
302
277
283
266
267
280
260
264
233
267
262
272
285
309
305
317
275
300
288
300
305
262
237
220
205
189
210
226
192
222
219
228
215
243


2001
5
11
11
44
35
0
0
XPS

1486.6
20.0
1E37
1E37
1E37
1E37
FAT
50.00
5.0
4.500
1E37
1200
1200
1E37
1E37


-1
binding energy
eV
289.0
-0.100
1
counts
d
pulse counting
0.200
100
70E-9
1E37
1E37
1E37
0
81
149282
263170
155944
156642
156356
157438
157049
157851
158574
158110
159279
160525
160828
161953
162561
163643
165249
165783
168073
168898
171505
174353
176412
178931
182137
184525
188670
192929
195643
200488
205200
210394
215749
221262
227768
234239
240023
244354
250850
254364
257670
261186
263036
263170
262515
260106
255842
250174
243417
236138
228307
218987
211078
203424
194968
188403
181705
176028
171367
167867
164071
161024
159253
156259
155760
154751
153381
152636
152593
151714
152422
151498
150429
149960
150177
150861
149849
150362
149971
149739
149473
149461
149282


2001
5
11
11
44
35
0
0
XPS

1486.6
20.0
1E37
1E37
1E37
1E37
FAT
50.00
5.0
4.500
1E37
1200
1200
1E37
1E37


-1
binding energy
eV
110.0
-0.100
1
counts
d
pulse counting
0.200
25
70E-9
1E37
1E37
1E37
0
151
10446
132127
20384
20193
20214
20212
19984
20394
20106
20039
19774
19916
19724
19909
20037
19838
19891
19997
19831
20006
19817
20028
19871
19912
19734
19684
19846
19958
19700
19636
19720
19419
19690
19384
19607
19377
19262
19180
19149
19013
19339
18671
18762
18576
18558
18225
18273
18214
18295
17894
17737
17797
17686
17676
17435
17247
17421
17227
17305
17013
17012
17015
17079
16699
16761
16740
16587
16452
16666
16600
16678
16347
16138
16251
16290
16143
16342
16421
16331
16702
17030
16932
17471
18071
18783
19465
20598
21652
23513
25759
28758
31911
35943
41365
46248
52858
60318
68126
76239
85549
93837
103868
110952
118447
124780
128331
131336
132127
129791
126244
120336
113292
104486
94554
84726
74490
64195
54957
46657
39664
33503
28351
24390
21434
19133
17392
16140
15283
14404
14086
13309
13158
12533
12314
12146
11902
11771
11530
11600
11318
11287
11117
11184
10943
10788
10681
10729
10581
10586
10659
10533
10446
10536


2001
5
11
11
44
35
0
0
XPS

1486.6
20.0
1E37
1E37
1E37
1E37
FAT
50.00
5.0
4.500
1E37
1200
1200
1E37
1E37


-1
binding energy
eV
15.0
-0.100
1
counts
d
pulse counting
0.200
100
70E-9
1E37
1E37
1E37
0
171
23691
35773
28485
28692
28756
28727
28623
28704
28584
28918
28719
28974
29044
29106
28815
29185
29250
29496
29403
29416
29714
29838
29824
30009
30271
30420
30357
30244
30693
30973
30876
31005
31255
31511
31818
31717
31965
31780
32322
32033
32291
33085
33192
33026
33626
33657
33466
33647
33860
33797
33917
33622
33816
33773
33727
33614
34139
33495
33608
33792
33915
33958
34002
33697
33720
33644
33823
34029
33981
34733
34531
35156
35279
35011
35284
35601
35773
35720
35549
35390
35393
35263
35088
35145
34682
34198
34088
34035
33468
33448
32913
32677
32563
31897
32151
31940
32013
32000
32588
32322
32223
32339
32509
32684
32588
32841
32709
33074
33211
33388
33479
33425
33841
33603
33841
33799
33877
33840
33854
33375
33607
33673
33560
33586
33067
33036
32469
32308
32082
31640
31041
31096
30609
30481
29589
29501
28930
28578
28015
27842
27320
26716
26760
26269
25750
25650
24966
24955
24952
24558
24542
24404
24401
24299
24489
24126
24212
24041
24085
23777
24152
23932
24048
24029
23846
23866
23873
24119
24124
23691
24109
24104
24041


2001
5
11
11
44
35
0
0
XPS

1486.6
20.0
1E37
1E37
1E37
1E37
FAT
50.00
5.0
4.500
1E37
1200
1200
1E37
1E37


-1
binding energy
eV
33.0
-0.100
1
counts
d
pulse counting
0.200
25
70E-9
1E37
1E37
1E37
0
71
0
0
0
0
0
0
0
0
0
0
0
0
0
0
0
0
0
0
0
0
0
0
0
0
0
0
0
0
0
0
0
0
0
0
0
0
0
0
0
0
0
0
0
0
0
0
0
0
0
0
0
0
0
0
0
0
0
0
0
0
0
0
0
0
0
0
0
0
0
0
0
0
0


2001
5
11
11
44
35
0
0
XPS

1486.6
20.0
1E37
1E37
1E37
1E37
FAT
50.00
5.0
4.500
1E37
1200
1200
1E37
1E37


-1
binding energy
eV
15.0
-0.100
1
counts
d
pulse counting
0.200
100
70E-9
1E37
1E37
1E37
0
171
0
0
0
0
0
0
0
0
0
0
0
0
0
0
0
0
0
0
0
0
0
0
0
0
0
0
0
0
0
0
0
0
0
0
0
0
0
0
0
0
0
0
0
0
0
0
0
0
0
0
0
0
0
0
0
0
0
0
0
0
0
0
0
0
0
0
0
0
0
0
0
0
0
0
0
0
0
0
0
0
0
0
0
0
0
0
0
0
0
0
0
0
0
0
0
0
0
0
0
0
0
0
0
0
0
0
0
0
0
0
0
0
0
0
0
0
0
0
0
0
0
0
0
0
0
0
0
0
0
0
0
0
0
0
0
0
0
0
0
0
0
0
0
0
0
0
0
0
0
0
0
0
0
0
0
0
0
0
0
0
0
0
0
0
0
0
0
0
0
0
0
0
0
end of experiment