File: gxps/gxps-2.1/examples/casaxps.vms
VAMAS Surface Chemical Analysis Standard Data Transfer Format 1988 May 4




6
Casa Info Follows
1
None
None
Experiment Type: XPS
SourceAnalyserAngle: Not Specified
NORM
REGULAR
3
1
None
d
0
0
0
0
3
None

2009
9
18
9
59
33
0
9
Casa Info Follows
1
Sm SG D(1) P(5)
0
1
CASA region (*None*) (*Shirley*) 1141.6219 1154.7469 1 1 0 0 299 542 275 9.3 (*NoTag*) 0
2
CASA comp (*None*) (*GL(30)*) Area 22608.296 0.001 10000000 -1 1 MFWHM 1.9217274 0.4 10 -1 1 Position 1151.6579 1136.7 1156.7 -1 1 RSF 1 MASS 0 INDEX -1 (*NoTag*)
CASA comp (*None*) (*GL(30)*) Area 17770.559 0.001 10000000 -1 1 MFWHM 2.2286028 0.4 10 -1 1 Position 1146.1424 1136.7 1156.7 -1 1 RSF 1 MASS 0 INDEX -1 (*NoTag*)
XPS
0
Al
1486.7
300
1e+037
1e+037
1e+037
1e+037
FAT
50
5
4.5
1e+037
2400
1200
1e+037
1e+037
None

-1
kinetic energy
eV
1136.7
0.1
1
Intensity
d
pulse counting
0.2
25
7e-008
1e+037
1e+037
1e+037
0
201
25629
38488
150630
150055
152310
150815
154280
154910
156045
154965
156690
157910
159700
160650
160675
159595
161675
160790
161785
160040
158745
160315
159240
160090
157845
157500
154905
155480
152610
153525
152695
151055
150855
150490
149505
149730
147300
147845
147520
146975
146030
145740
147160
146980
144365
144175
146025
143260
144960
144555
144625
144360
144420
143395
145175
144090
145675
144825
145070
145390
144455
146395
147430
148280
145145
146205
147180
148905
146870
147960
148910
149705
149630
150325
150785
151515
152590
152145
153780
154640
156200
155160
158415
159225
159825
160405
162865
165045
166980
169275
170855
175355
174685
177515
177225
181605
182230
182250
182335
182830
184025
181140
179300
177695
175380
170690
169455
166340
163270
158145
155790
153990
151590
151380
149525
149000
146915
146245
145790
145895
145065
146550
145555
145240
146710
147325
146265
147625
148820
147340
149790
149730
152245
150275
153455
152195
154565
157550
161500
163225
166320
166355
168790
172980
175950
178945
184010
187295
188755
189890
191920
192440
192365
190845
188615
185125
182100
179475
174290
168460
164695
159740
153405
148505
145255
143210
141175
137870
136295
135945
133555
133820
133495
131995
132580
130725
129740
131760
131710
130050
129550
129160
129310
131120
128600
131135
130620
129135
129780
130425
129585
129420
128685
130410
130470
129330
129915
130280
128230
129850
128495
128775
128145
None

2009
9
18
9
59
33
0
7
Casa Info Follows
0
0
1
CASA region (*None*) (*Shirley*) 1385.1766 1389.6297 1 1 0 0 299 542 275 9.3 (*NoTag*) 0
1
CASA comp (*None*) (*GL(30)*) Area 67017.591 0.001 10000000 -1 1 MFWHM 1.6108691 0.34 8.5 -1 1 Position 1387.3603 1376.7 1396.7 -1 1 RSF 1 MASS 0 INDEX -1 (*NoTag*)
XPS
0
Al
1486.7
300
1e+037
1e+037
1e+037
1e+037
FAT
50
5
4.5
1e+037
2400
1200
1e+037
1e+037
None

-1
kinetic energy
eV
1376.7
0.1
1
Intensity
d
pulse counting
0.2
25
7e-008
1e+037
1e+037
1e+037
0
201
9054
50406
64275
64420
63335
63195
63130
63100
62550
63990
63530
63160
61875
63330
63330
62445
63495
63390
62375
61935
62685
63610
62210
61750
63455
63005
61830
61565
62380
62625
63375
62205
63665
63200
63140
62175
62660
63450
62320
62570
62265
62580
61995
61715
62665
62285
63660
65315
65700
65765
67015
68115
70335
70095
72490
74810
75535
79700
81400
84245
87020
90025
91905
92825
96535
98900
99355
99590
100780
101085
99560
99665
96985
97095
94375
92450
91265
87730
85860
83540
81285
80175
77060
77240
74040
74355
73810
74625
75000
75830
77160
80250
84645
90060
94165
103140
112345
123035
135065
148560
163215
178155
193810
209005
223420
234240
240525
249265
251870
252030
246945
236780
226575
211985
197500
179185
162960
146285
130110
116145
100860
91420
81470
73220
67345
63500
58765
55860
55270
53730
51830
50590
50950
49900
49515
48150
47895
48260
47040
46375
46300
46405
46885
46615
47335
45935
46765
45315
45590
45935
45315
45950
45440
46355
46265
47060
47125
46570
46765
47790
47850
47840
46965
47485
47910
48170
47925
47905
47840
48305
47110
47555
47655
47030
47220
47345
46085
46405
46430
46690
46290
47065
45950
46250
46395
45485
45490
45270
46285
45650
46310
46530
47070
47000
48265
49110
48675
50060
51635
51680
52200
53410
54760
None

2009
9
18
9
59
33
0
5
Casa Info Follows
0
0
0
0
XPS
0
Al
1486.7
300
1e+037
1e+037
1e+037
1e+037
FAT
50
5
4.5
1e+037
2400
1200
1e+037
1e+037
None

-1
kinetic energy
eV
486.7
1
1
Intensity
d
pulse counting
0.2
1
7e-008
1e+037
1e+037
1e+037
0
1001
217
6240
1092
1103.8
1078.2
1046.6
1060.2
1018.8
1043
1046.8
1031.2
1024.6
1005.8
1030.4
1010.8
1019.2
1026.4
1047.8
1090.2
1132.2
1134.4
1174
1248
1239.4
1175
1141.6
1108.4
1045.2
1031
972
961.2
942.6
908.4
876
856.2
832.2
796.6
819.2
823
792.8
784.8
810
798.2
771
806.2
783.8
787.2
781.4
775.8
779.6
776.6
767
767.2
776.2
776.8
763.4
777.4
767.4
755.8
767.8
769.8
750
751.2
748.6
748.4
741.8
764.8
765.8
739.4
774.8
762.4
736.8
751.8
727
742.2
740.4
729.2
744.8
717.6
733.8
712.2
731.4
726
730.2
722.4
709.6
696.8
721.4
711.6
715.6
709.4
706.4
721.8
710.6
721.4
721.2
717.6
710.8
699
694.6
704.8
705.6
676.8
690
694
667.8
688
693.4
680.4
688.2
682
672.4
684.2
675.6
693.2
674.8
677
663.4
661.4
660.2
683.2
663.4
667.6
694.8
668.4
662
650.6
647
658.8
656.4
656.6
655
649
636.8
635.6
647.2
634.6
661
648
634.4
638.2
626.6
644.2
642.8
652.6
632
629.6
633.2
619.2
617
636.4
617.8
634
620
618.2
620.8
606.2
613.4
622
621.6
598.6
614.6
630
612.8
611.6
625.2
622.8
620.6
614.2
638
633.8
616.4
607.6
604.4
595.2
578.4
582.2
584.8
567
566.2
572.4
557.8
568.8
574.6
577
558.6
578.2
554.8
562
564
566.8
545.2
557.8
554.4
568.8
545
564.4
566.4
519.4
557.2
548.2
547.2
536
538.4
539
548.6
563.4
529.6
513.4
532.6
533.6
543.4
539.4
547.2
548
550.4
548.6
517.2
546.2
545.6
537.6
543.4
531.2
528.8
521.6
544
532.4
496.4
517.4
523.8
526.6
514.4
518.4
495.4
518.6
489.2
512
528.2
510.8
502
506.2
500.8
512
511
486.8
499.2
496.2
494.8
489.8
486.4
485.8
495.4
496.2
495
488.2
502.8
502
485.4
499.8
491.6
488.6
500
481.8
489.4
472.2
490.2
472.6
489.4
477.4
493
476.8
493
467.4
468.4
479.6
483.4
497
465.8
492.6
469.2
472.8
481.6
455.2
460.6
489.2
472.4
459
451
454
479.4
482.8
463.6
451.4
461.2
437.8
439.2
454.2
460.8
435.8
448.6
445.6
435.4
443.6
433.2
431.6
444
427.8
425.4
439.6
424.6
421.8
433.4
443
436.8
450.4
460.4
489.8
461.4
440.2
406.2
418.6
412.8
434.4
420.4
397.6
424
409.2
418.8
409.4
427.2
423.8
416.8
401.8
411.8
410.6
434
404.6
410.4
422.8
421.2
407.6
400.8
416.4
401.2
406.2
389.8
411.6
409.2
401
423.4
402.8
390.8
408
405.2
399
395.6
409
395
401.8
400.8
383
396
398.8
391.8
385.6
398
387.4
402.6
391.4
390.2
383.2
384.8
390.4
386.8
393.6
400
375.8
385.6
388
403.6
385.8
357.6
381.4
389.4
389
383.4
374.8
372.8
391
385.4
386
389.6
378.4
385.4
385.8
383.4
384
388.2
396.4
379.6
380.2
386.8
379
389.6
366.6
384.2
398.6
379.4
374
383.4
369.2
385.6
378.2
394
393.8
388
384.4
394.6
382.8
382.2
382
377.4
398.4
386.2
380.2
387
381.6
382.8
368.6
390
382
380.2
381.6
377.6
386.4
385
406
374
377.4
382.4
387
408.4
407.8
400.8
398.2
403.8
370.2
393
386.6
387.8
373.8
365.6
361.2
356.4
353.4
356.2
352
332
346.4
334.2
327.4
333.2
328
324
328.4
348.6
349.8
431.6
690.6
1062.6
845.2
535
372.4
311.4
303.4
302.2
299.2
302.6
321.4
321.8
335.2
318.6
285.4
287.6
267.2
274.2
282.4
273.6
259
283.6
273.4
268.4
279.2
273.6
267
278.6
276.8
266
276.8
251.4
268
263.8
266
292.6
265.6
270.8
277.8
271.8
268.6
261.8
271.8
267
268
275
273.4
260.6
273.2
263.6
264
261.2
261.4
267.4
278.4
265.6
261.8
269.4
266.2
276.8
247.6
249
255.2
255.8
256.4
252.2
268.4
258.4
258
261.6
273
269.8
256.8
250.8
263.4
253
278.4
255.6
241.8
265.2
260.4
265.2
269.6
264.8
263.6
250
246.2
258.2
276.8
264.4
259
248
264.4
265.6
268.6
259.4
257.6
252
265.4
264
256.2
261.2
257.8
266.4
261.8
252.6
236.4
248.2
253.2
261.4
240.4
241.8
271.6
252.4
244
249.6
255.8
253.6
249.2
241.6
245.2
249.6
250.6
248
252
242.4
259.8
255
249.8
256.6
254.2
248.6
253
255.2
252.2
261
235.6
247.2
251
255.2
252.4
248.8
252.4
248.2
243.4
258.6
258.2
248
240.2
254.4
254.8
255.4
245.8
258.2
253.6
255
239.4
257
249
260
257
255.2
252.2
250.4
249.2
248.2
262.4
262.4
273.4
262
254
240.4
239.8
251.4
249
250.6
253.8
239.8
258.8
258.4
246.4
267.4
247.8
261.8
269.6
287.4
273.4
255
252
237.6
265.8
255.8
282.8
305.4
304.8
264
248.8
256
302.4
342
257.2
228
231
231.6
227.6
213.8
221.4
213.4
231.4
199.2
232
215.8
221.6
212.8
213.2
222.8
202.4
216.6
215.8
214.4
218.6
223.4
224.8
217.8
219
227.6
227.8
222.2
207.4
213.2
214.8
225.6
218.2
204
213.4
212.8
206.6
201
199.8
200
202.8
194.8
202
200
204.2
229.2
241
291.6
342.4
317.8
236.6
206
206.6
182
188.2
207.2
186.4
214.4
195.2
211.8
202.2
201.2
194
192.6
198.8
197.4
185.4
193.2
193.4
184
192.2
186.2
183
199.8
182
186.4
193.8
192.6
198.2
186.6
185
192.6
195.4
187.2
188.2
195
192
189.6
185.4
189.4
196.4
182.4
190.4
195.4
187.8
194.6
197.2
194.4
205.4
197
202.6
207.2
201.8
191
197.6
205.4
205.6
204.4
200.2
197.4
199.6
200.6
198.8
199.4
206.4
200
205.6
199.4
209.4
197
203.6
193.4
220.6
210.2
199.2
212.8
194.2
208.8
197.8
203.2
202.4
191.2
214.8
210.8
209.2
206.4
202
205.4
203.8
192.4
196.4
214
213.4
209.6
224.6
216.2
220.8
206.4
220
237.2
217.2
223.2
207.4
216.8
204.4
202.2
197.8
203.4
209.8
208.4
201.2
214.6
213.6
224.6
246.4
253.2
256.8
244.4
234.2
198
209
194.2
180.8
181.8
173
173
181
176.4
189.6
229
220.4
216.4
283.4
419.8
374.2
223
179.2
152
158.6
141.8
147.8
142.8
162.2
162
154.8
146.2
157.8
133.2
154.4
152.8
155.2
152.2
139.8
139.8
139.6
129
133.6
131.8
129
130.2
137.2
135.2
130.4
141.8
145.6
149
173.4
180.6
171.8
151.2
140.8
112.8
111.8
101.8
106
107.6
111.4
107.8
107.4
117.2
156.4
163.8
136.4
139.4
335.6
370.6
128.4
83.4
82.4
70
81.4
75.6
78
85.2
90.8
86
73.6
73
64.4
66.2
66.8
70.2
64.2
62.6
62.8
66.4
63.8
63.6
67
63.6
61.6
66.2
62.4
61
70.6
60.2
65.8
63.6
60.8
57.6
70.2
57.2
60.8
56.8
58.2
64.6
67
62.2
60.6
62.8
64.4
65.4
68.8
58.8
65.4
60
61.6
61.8
56.4
61.8
60.8
51.8
54.8
56.6
56
55.6
59
55.8
53.6
47.4
50.6
52.6
56
57.2
50.6
56.8
59
65.6
63
60.4
54.4
57.6
55.2
52
48.2
48.2
52.8
52.8
43.4
47.6
46
52
47.2
51
52
52.4
52.4
55.6
56.8
54
54.2
51.2
55.6
50.8
48.2
end of experiment